Workbook

Sheet Judging
A1: display_id | B1: query_id | C1: question | D1: reference_answer | E1: chunk_id | F1: source_document_title | G1: candidate_chunk | H1: relevance_grade | I1: rationale | J1: batch | K1: status
A2: v2q-001-candidate-19 | B2: v2q-001 | C2: What is the minimum house size specified under PMAY-G? | D2: The minimum house size is 25 square metres, including a dedicated hygienic cooking area. | E2: pilot-v2-doc-pm-gkay-0000-c29b96f46a80 | F2: Pradhan Mantri Garib Kalyan Anna Yojana | G2: Pradhan Mantri Garib Kalyan Anna Yojana. Ministry Of Finance. Department Of Economic Affairs. The scheme "Pradhan Mantri Garib Kalyan Anna Yojana (PMGKAY)" has been launched by the Department of Food and Public Distribution, Ministry of Consumer Affairs, Food and Public Distribution, Government of India, and aims to ensure food security for the poor and vulnerable sections of the country by providing free food foodgrains. It was announced on 26 March 2020 during the COVID-19 pandemic and is operated by the Department of Food and Public Distribution under the Ministry of Consumer Affairs, Food and Public Distribution. Through this scheme, free foodgrains (rice or wheat, depending on the State) are provided to eligible ration card holders covered under the National Food Security Act, 2013, namely Antyodaya Anna Yojana (AAY) households and Priority Households (PHH). From 1 January 2023, the scheme was integrated into the food security framework, and foodgrains earlier given at the highly subsidised rates of ₹1, ₹2, and ₹3 per kilogram for coarse cereals, wheat, and rice, respectively, are now provided free of cost. The scheme has been extended by the Union Cabinet for 5 years starting from 1 January 2024 and is approved for continuation till 31 December 2028, with a total financial outlay of ₹11.80 lakh crore (₹11,80,000 crore). The scheme is implemented through the Targeted Public Distribution System (TPDS) by the state governments and Union Territory Administrations, with foodgrain allocation by the Government of India.. The scheme aims to ensure food security for the poor. Through this scheme, free foodgrains are provided to eligible ration card holders under the National Food Security Act, 2013.. Antyodaya Anna Yojana (AAY) families receive 35 kilograms of foodgrains per family per month. Priority Household (PHH) beneficiaries receive 5 kilograms of foodgrains per person per month. The foodgrains are provided as | H2: 0 | J2: =INT((ROW()-2)/50)+1 -> 1 | K2: =IF(H2="","Pending",IF(OR(H2="0",H2="1",H2="2",H2="U"),"Complete","Invalid")) -> Complete
A3: v2q-004-candidate-10 | B3: v2q-004 | C3: What is the maximum micro-loan amount stated for PMMY? | D3: PMMY facilitates micro-credit loans up to ₹20 lakh for eligible income-generating micro-enterprises. | E3: pilot-v2-doc-pmegp-0002-f67d4c730011 | F3: Prime Minister's Employment Generation Programme | G3: under the Business/Service sector is ₹20,00,000. The balance amount (excluding the own contribution)of the total project cost will be provided by Banks. If the total project cost exceeds ₹50,00,000 or ₹20,00,000 for Manufacturing and Service/Business sector respectively, the balance amount may be provided by Banks without any Government subsidy. 2. 2nd Loan for Upgradation of Existing PMEGP / REGP / MUDRA Units a) Categories of beneficiaries under PMEGP (for upgradation of existing units): All Categories b) Beneficiary's contribution (of project cost): 10% c) Rate of Subsidy (of project cost): 15% (20% in NER and Hill States). Note: The maximum cost of the project/unit admissible for Margin Money subsidy under the Manufacturing sector for upgradation is ₹10,00,00,000. The maximum subsidy would be ₹15,00,000 (₹20,00,000 for NER and Hill States). The maximum cost of the project/unit admissible for Margin Money subsidy under the Business/Service sector for upgradation is ₹25,00,000. The maximum subsidy would be ₹3,75,000 (₹5,00,000 for NER and Hill States). The balance amount (excluding the own contribution)of the total project cost will be provided by Banks. If the total project cost exceeds ₹10,00,00,000 or ₹25,00,000 for Manufacturing and Service/Business sector respectively, the balance amount may be provided by banks without any Government subsidy.. For PMEGP new enterprises (Units) Any individual, above 18 years of age. There will be no income ceiling for assistance in setting up projects under PMEGP. For setting up of project costing above Rs.10 lakh in the Manufacturing sector and above ₹ 5,00,000 in the Business /Service sector, the beneficiaries should possess at least VIII standard pass educational qualification. Assistance under the scheme is available only for new projects sanctioned specifically under the PMEGP. Existing Units (under PMRY, REGP, or any other scheme of the Government of India or State Government) and the units that have already availed | H3: 0 | J3: =INT((ROW()-2)/50)+1 -> 1 | K3: =IF(H3="","Pending",IF(OR(H3="0",H3="1",H3="2",H3="U"),"Complete","Invalid")) -> Complete
A4: v2q-005-candidate-12 | B4: v2q-005 | C4: How many days of wage employment does MGNREGA guarantee a rural household in a financial year? | D4: MGNREGA guarantees at least 100 days of wage employment per financial year to a rural household whose adult members volunteer for unskilled work. | E4: pilot-v2-doc-pm-kmy-guidelines-0006-2652020c834e | F4: Pradhan Mantri Kisan Maan Dhan Yojana Operational Guidelines | G4: same day every month as enrolment date. The beneficiaries may also chose an option to pay their contributions on quarterly, 4-monthly or half-yearly basis. Such contributions will fall due on the same day of such period as the date of enrollment; 4 (x) The amount of the monthly contribution shall range between Rs.55 to Rs.200 per month depending upon the age of entry of the farmers into the Scheme, as per the following contribution chart: Superannuation Member's Government’s Total contribution Entry Age Age contribution (Rs.) contribution (Rs.) (Rs.) (1) (2) (3) (4) (5) 18 60 55 55 110 19 60 58 58 116 20 60 61 61 122 21 60 64 64 128 22 60 68 68 136 23 60 72 72 144 24 60 76 76 152 25 60 80 80 160 26 60 85 85 170 27 60 90 90 180 28 60 95 95 190 29 60 100 100 200 30 60 105 105 210 31 60 110 110 220 32 60 120 120 240 33 60 130 130 260 34 60 140 140 280 35 60 150 150 300 36 60 160 160 320 37 60 170 170 340 38 60 180 180 360 39 60 190 190 380 40 60 200 200 400 (xi) In case of death of subscriber before vesting date, the spouse of subscriber shall have an option of continuing the scheme by payment of remaining contributions under the scheme, provided she/he is not already an SMF beneficiary of the Scheme. The rate of contribution and vesting date shall remain the same. Pension accruals will be calculated as if subscriber were to be alive on the vesting date. However, the same pension would be payable to the spouse. Upon death of spouse after vesting date, pension corpus would be transferred back to | H4: 0 | J4: =INT((ROW()-2)/50)+1 -> 1 | K4: =IF(H4="","Pending",IF(OR(H4="0",H4="1",H4="2",H4="U"),"Complete","Invalid")) -> Complete
A5: v2q-027-candidate-14 | B5: v2q-027 | C5: What livelihood mechanism does PM SVANidhi offer street vendors, and which other programme from its ministry addresses housing shortages for eligible urban households? | D5: PM SVANidhi offers street vendors collateral-free working-capital loans, interest subsidy, and digital-payment incentives. PMAY-U, under the same Ministry of Housing and Urban Affairs, provides housing support for eligible urban households. | E5: pilot-v2-doc-pm-kisan-guidelines-0000-bbe94f08550e | F5: PM-KISAN Operational Guidelines | G5: PRADHAN MANTRI KISAN SAMMAN NIDHI SCHEME (PM-KISAN SCHEME) OPERATIONAL GUIDELINES (REVISED AS ON 29.03.2020) MINISTRY OF AGRICULTURE & FARMERS’ WELFARE DEPARTMENT OF AGRICULTURE, COOPERATION & FARMERS’ WELFARE (DAC&FW) 1 PRADHAN MANTRI KISAN SAMMAN NIDHI (PM-KISAN) SCHEME OPERATIONAL GUIDELINES 1. Scheme With a view to provide income support to all landholding farmers’ families in the country, having cultivable land, the Central Government has implemented a Central Sector Scheme, namely, “Pradhan Mantri Kisan Samman Nidhi (PM-KISAN)”. 2. Objective and Benefits The scheme aims to supplement the financial needs of all landholding farmers’ families in procuring various inputs to ensure proper crop health and appropriate yields, commensurate with the anticipated farm income as well as for domestic needs. Under the Scheme an amount of Rs.6000/- per year is released by the Central Government online directly into the bank accounts of the eligible farmers under Direct Benefit Transfer mode, subject to certain exclusions. 3. Definition of farmer’s family A landholder farmer’s family is defined as “a family comprising of husband, wife and minor children who owns cultivable land as per land records of the concerned State/UT”. The existing land-ownership system will be used for identification of beneficiaries for calculation of benefit. 4 Exclusions 4.1 The following categories of beneficiaries of higher economic status shall not be eligible for benefit under the scheme: (a) All Institutional Land holders; and (b) Farmer families in which one or more of its members belong to following categories : i) Former and present holders of constitutional posts ii) Former and present Ministers / State Ministers and former / present Members of Lok Sabha / Rajya Sabha / State Legislative Assemblies / State Legislative Councils, former and present Mayors of Municipal Corporations, former and present Chairpersons of District Panchayats. iii) All serving or retired officers and employees of Central / | H5: 0 | J5: =INT((ROW()-2)/50)+1 -> 1 | K5: =IF(H5="","Pending",IF(OR(H5="0",H5="1",H5="2",H5="U"),"Complete","Invalid")) -> Complete
A6: v2q-029-candidate-19 | B6: v2q-029 | C6: What migrant-focused facility distinguishes Ujjwala 2.0, and what clean-cooking transition was established by its predecessor programme? | D6: Ujjwala 2.0 added 1.6 crore LPG connections with a special facility for migrant households. Its predecessor, Pradhan Mantri Ujjwala Yojana, sought to replace traditional cooking fuels with LPG access for rural and deprived households. | E6: pilot-v2-doc-pm-gkay-0000-c29b96f46a80 | F6: Pradhan Mantri Garib Kalyan Anna Yojana | G6: Pradhan Mantri Garib Kalyan Anna Yojana. Ministry Of Finance. Department Of Economic Affairs. The scheme "Pradhan Mantri Garib Kalyan Anna Yojana (PMGKAY)" has been launched by the Department of Food and Public Distribution, Ministry of Consumer Affairs, Food and Public Distribution, Government of India, and aims to ensure food security for the poor and vulnerable sections of the country by providing free food foodgrains. It was announced on 26 March 2020 during the COVID-19 pandemic and is operated by the Department of Food and Public Distribution under the Ministry of Consumer Affairs, Food and Public Distribution. Through this scheme, free foodgrains (rice or wheat, depending on the State) are provided to eligible ration card holders covered under the National Food Security Act, 2013, namely Antyodaya Anna Yojana (AAY) households and Priority Households (PHH). From 1 January 2023, the scheme was integrated into the food security framework, and foodgrains earlier given at the highly subsidised rates of ₹1, ₹2, and ₹3 per kilogram for coarse cereals, wheat, and rice, respectively, are now provided free of cost. The scheme has been extended by the Union Cabinet for 5 years starting from 1 January 2024 and is approved for continuation till 31 December 2028, with a total financial outlay of ₹11.80 lakh crore (₹11,80,000 crore). The scheme is implemented through the Targeted Public Distribution System (TPDS) by the state governments and Union Territory Administrations, with foodgrain allocation by the Government of India.. The scheme aims to ensure food security for the poor. Through this scheme, free foodgrains are provided to eligible ration card holders under the National Food Security Act, 2013.. Antyodaya Anna Yojana (AAY) families receive 35 kilograms of foodgrains per family per month. Priority Household (PHH) beneficiaries receive 5 kilograms of foodgrains per person per month. The foodgrains are provided as | H6: 0 | J6: =INT((ROW()-2)/50)+1 -> 1 | K6: =IF(H6="","Pending",IF(OR(H6="0",H6="1",H6="2",H6="U"),"Complete","Invalid")) -> Complete
A7: v2q-034-candidate-08 | B7: v2q-034 | C7: How do three programmes meet distinct household needs for rural housing, clean cooking, and food security? | D7: PMAY-G supports pucca rural housing with basic amenities; PMUY provides LPG access to deprived households replacing traditional cooking fuels; PMGKAY provides free foodgrains to eligible AAY and PHH ration-card holders. | E7: pilot-v2-doc-pmegp-0003-43256e8e6645 | F7: Prime Minister's Employment Generation Programme | G7: sector and above ₹ 5,00,000 in the Business /Service sector, the beneficiaries should possess at least VIII standard pass educational qualification. Assistance under the scheme is available only for new projects sanctioned specifically under the PMEGP. Existing Units (under PMRY, REGP, or any other scheme of the Government of India or State Government) and the units that have already availed of Government Subsidy under any other scheme of the Government of India or State Government are not eligible. For up-gradation of existing PMEGP / REGP / MUDRA units Margin Money(subsidy)claimed under PMEGP has to be successfully adjusted on the completion of the lock-in period of 3 years. The first loan under PMEGP/REGP/MUDRA has to be successfully repaid in the stipulated time. The unit is profit-making with good turnover and has the potential for further growth in turnover and profit with modernization/upgrading of the technology. Reservation / Preference / Priority Priority will be given to the persons affected by natural calamities/disasters in the areas which are declared as affected by "disaster" as defined under Section 2(d) of the Disaster Management Act, 2005 by the Ministry of Home Affairs.. For PMEGP new enterprises (Units): Existing Units (under PMRY, REGP, or any other scheme of the Government of India or State Government) and the units that have already availed of Government Subsidy under any other scheme of the Government of India or State Government are not eligible. Only one person from one family is eligible for obtaining financial assistance for setting up of projects under PMEGP. The 'family’ includes self and spouse. Negative List of Activities: The following list of activities will not be permitted under PMEGP for setting up of micro enterprises/ projects/units:- Any Industry/ Business connected with Meat(slaughtered), i.e., processing, canning and/or serving items made of it as food, production/Manufacturing or | H7: 0 | J7: =INT((ROW()-2)/50)+1 -> 1 | K7: =IF(H7="","Pending",IF(OR(H7="0",H7="1",H7="2",H7="U"),"Complete","Invalid")) -> Complete
A8: v2q-019-candidate-22 | B8: v2q-019 | C8: What role does the Ministry of Petroleum and Natural Gas have in Ujjwala 2.0? | D8: The ministry introduced Ujjwala 2.0 to provide LPG connections and promote clean cooking fuel among poor, rural, and deprived households. | E8: pilot-v2-doc-apy-0000-c43dd88d7899 | F8: Atal Pension Yojana | G8: Atal Pension Yojana. Ministry Of Finance. Department of Financial Service. Banks. Atal Pension Yojana (APY) is an old age income security scheme for a savings account holder in the age group of 18-40 years who is not an income tax-payee. The scheme helps in addressing the longevity risks among the workers in the unorganized sector and encourages the workers to voluntarily save for their retirement. Focus of APY The scheme is mainly targeted at the poor, the under-privileged and workers in the unorganized sector. APY Subscriber Contribution Chart - https://www.npscra.nsdl.co.in/nsdl/scheme-details/APYSubscribersContributionChart1.pdf Charges and fees and overdue interest under APY: The charges and fees and the overdue interest for non-payment or delayed payment of prescribed contribution amount shall be levied on the subscribers of APY. These charges and their method of application shall be prescribed by PFRDA from time to time, in consultation with the Central Government. Raising Grievance Under APY A subscriber can raise grievance anytime free of cost from anywhere by visiting: www.npscra.nsdl.co.in &gt;&gt;Home &gt;&gt; select: NPS-Lite or through CGMS Subscriber raising the grievance will be allotted a token number against the grievance raised. Subscriber may check the status of the grievance under “Check the status of Grievance / Enquiry already registered”.. Atal Pension Yojana (APY) is an old age income security scheme for a savings account holder in the age group of 18-40 years, who is not an income tax-payee. It helps to address longevity risks among workers in unorganized sector and encourages the workers to voluntarily save for retirement.. Upon exit on attaining 60 years The subscriber shall receive the following three benefits on attaining the age of 60: (i) Guaranteed minimum pension amount: Each subscriber under APY shall receive a guaranteed minimum pension of Rs. 1000/- per month or Rs. 2000/- per month or Rs. 3000/- per | H8: 0 | J8: =INT((ROW()-2)/50)+1 -> 1 | K8: =IF(H8="","Pending",IF(OR(H8="0",H8="1",H8="2",H8="U"),"Complete","Invalid")) -> Complete
A9: v2q-007-candidate-08 | B9: v2q-007 | C9: What is the full form of PMJJBY, and which event does its life insurance cover? | D9: PMJJBY stands for Pradhan Mantri Jeevan Jyoti Bima Yojana and provides life-insurance cover for death due to any reason. | E9: pilot-v2-doc-pmjdy-0001-95c3d046d79a | F9: Pradhan Mantri Jan Dhan Yojana | G9: Basic Savings Bank Deposit Account (BSBDA) Any Indian citizen eligible to open a regular bank account can open a BSBDA. Such an account does not require any minimum balance maintenance. The account holders can use both bank branches, ATMs and Banking Correspondents (BCs) for depositing and withdrawing cash. However, one cannot withdraw cash more than four times a month. Small Account/Chota Khata Under Jan Dhan Yojana, people can open small bank accounts without presenting legal documents. These accounts would be valid normally for a period of twelve months. Thereafter, such accounts would be allowed to a continue for a further period of twelve more months, if the account-holder provides a document showing that he/she has applied for any of the Officially Valid Document, within 12 months of opening the small account. RuPay Debit Card with inbuilt accident insurance Under PMJDY, a free Rupay debit card, with inbuilt accident insurance cover of Rs.2 lakhs (Rs 1 lakh for accounts opened before 28.08.2018), is issued to all beneficiaries. Overdraft Facility Under PMJDY, beneficiaries can avail OD facility upto Rs. 10,000/-. Business Correspondents (BCs)/Bank Mitras BCs/Bank Mitras are retail agents engaged by banks for providing banking services at locations other than a bank branch/ATM. It is mainly meant for the rural areas, where bank branches are far-flung. BCs/Bank Mitras connect with the residents and guide them with banking solutions such as savings accounts, deposits, payments and withdrawals, mini account statements, etc. Banks with their strong network of BCs/Bank Mitras are providing hassle free services to the customers in remote / rural areas.. The applicant should be an Indian National. If minors above ten years apply, they will require support from their legal guardians for administering their PMJDY account.. Step 1- Go to the official portal of PMJDY. Step 2- Under the &quot;e-documents&quot; section, | H9: 0 | J9: =INT((ROW()-2)/50)+1 -> 1 | K9: =IF(H9="","Pending",IF(OR(H9="0",H9="1",H9="2",H9="U"),"Complete","Invalid")) -> Complete
A10: v2q-029-candidate-13 | B10: v2q-029 | C10: What migrant-focused facility distinguishes Ujjwala 2.0, and what clean-cooking transition was established by its predecessor programme? | D10: Ujjwala 2.0 added 1.6 crore LPG connections with a special facility for migrant households. Its predecessor, Pradhan Mantri Ujjwala Yojana, sought to replace traditional cooking fuels with LPG access for rural and deprived households. | E10: pilot-v2-doc-pmay-g-0001-db2db8af1543 | F10: Pradhan Mantri Awaas Yojana - Gramin | G10: years from 2016-17 to 2018-19 and enable construction of quality houses by the beneficiaries using local materials, designs and trained masons. For houses to become homes, adoption of a habitat approach through convergence is proposed.. Launch on 1st April 2016, Pradhan Mantri Awaas Yojana Gramin (PMAY-G) is centre's flagship mission by the Ministry of Rural Development (MoRD), implemented by the Ministry of Housing and Urban Affairs (MoHUA). PMAY-G addresses the rural housing shortage and bridges the housing deficit in rural areas. Financial Assistance of ₹ 1,20,000 per unit for plain areas; and ₹ 1,30,000 per unit for hilly areas, difficult areas, and IAP districts (Himalayan states, North-Eastern states, and Union Territories of Jammu & Kashmir). A willing beneficiary can avail of institutional finance (loan) of up to ₹ 70,000 at 3% lower interest rate, to build a permanent house. The maximum principal amount for which subsidy can be sought is ₹ 2,00,000. The minimum size of the house shall be is 25 sq m including a dedicated area for hygienic cooking. In convergence with Swachh Bharat Mission-Gramin (SBM-G), the beneficiaries get financial assistance of up to ₹ 12,000 for the construction of toilets. In convergence with MGNREGA, the beneficiary is entitled to employment as unskilled labor (Rural Mason Training) at ₹ 90.95 per day for 95 days. In convergence with Pradhan Mantri Ujjwala Yojana, one LPG connection per house is provided. Convergence with different government programmes for piped drinking water, electricity connection, clean & efficient cooking fuel, treatment of social and liquid waste, etc. Payments are made electronically directly to bank accounts or post office accounts that are linked to Aadhaar. Note: Beneficiaries are identified using the "Housing Deprivation Parameters" from the Socio-Economic and Caste Census (SECC) 2011, further verified by the Gram Sabhas.. The universe of eligible beneficiaries under | H10: 0 | J10: =INT((ROW()-2)/50)+1 -> 1 | K10: =IF(H10="","Pending",IF(OR(H10="0",H10="1",H10="2",H10="U"),"Complete","Invalid")) -> Complete
A11: v2q-021-candidate-12 | B11: v2q-021 | C11: How do insurance companies and banks participate in PMFBY? | D11: PMFBY is implemented through a network of insurance companies and banks to provide crop-insurance protection to farmers. | E11: pilot-v2-doc-ab-pmjay-0001-a632a7205efc | F11: Ayushman Bharat - Pradhan Mantri Jan Arogya Yojana | G11: per family per year for secondary and tertiary hospitalization to poor and vulnerable families.. AB PM-JAY is a health insurance scheme for low-income families in rural and urban areas. The scheme aims to provide affordable healthcare facilities to the Poor. It is the largest health assurance scheme in the world which aims at providing a health cover of ₹5,00,000/- per family per year.. Financial Health Insurance Cover: Annual Hospitalization Coverage: Cashless coverage up to ₹5,00,000/- per family per year.- Comprehensive Treatment Costs: Covers consultation, medicines, diagnostics, surgery, ICU, implants, accommodation, and food.- Pre and Post Hospitalization Support: Covers 3 days pre-hospitalization and 15 days post-hospitalization expenses.- Treatment Complication Coverage: Covers complications arising during treatment. Coverage Features: Pre-Existing Disease Coverage: Covers all pre-existing diseases from day one.- No Family Size Limit: No restriction on age, gender, or family size.- Nationwide Portability: Benefits available across India in empanelled hospitals.- Wide Procedure Coverage: Covers approximately 1,929 medical procedures.. Rural Beneficiaries Out of the total seven deprivation criteria for rural areas, PM-JAY covered all such families who fall into at least one of the following six deprivation criteria and automatic inclusion(Destitute/ living on alms, manual scavenger households, primitive tribal group, legally released bonded labour) criteria: Only one room with kucha walls and kucha roof No adult member between ages 16 to 59 Households with no adult male member between ages 16 to 59 Disabled member and no able-bodied adult member SC/ST households Landless households deriving a major part of their income from manual casual labour Automatically includedHouseholds without shelter Destitute/ living on alms, Manual scavenger families, Primitive tribal groups, Legally released bonded labour. Urban Beneficiaries For urban areas, the following 11 occupational categories of workers are eligible for the scheme: Ragpicker Beggar Domestic worker Street vendor/ Cobbler/hawker / other service provider working on streets | H11: 0 | J11: =INT((ROW()-2)/50)+1 -> 1 | K11: =IF(H11="","Pending",IF(OR(H11="0",H11="1",H11="2",H11="U"),"Complete","Invalid")) -> Complete
A12: v2q-002-candidate-07 | B12: v2q-002 | C12: What maximum premium rates can farmers pay under PMFBY for Kharif, Rabi, and annual commercial or horticultural crops? | D12: Farmers pay at most 2% for Kharif food and oilseed crops, 1.5% for Rabi food and oilseed crops, and 5% for annual commercial or horticultural crops. | E12: pilot-v2-doc-pmay-g-0001-db2db8af1543 | F12: Pradhan Mantri Awaas Yojana - Gramin | G12: years from 2016-17 to 2018-19 and enable construction of quality houses by the beneficiaries using local materials, designs and trained masons. For houses to become homes, adoption of a habitat approach through convergence is proposed.. Launch on 1st April 2016, Pradhan Mantri Awaas Yojana Gramin (PMAY-G) is centre's flagship mission by the Ministry of Rural Development (MoRD), implemented by the Ministry of Housing and Urban Affairs (MoHUA). PMAY-G addresses the rural housing shortage and bridges the housing deficit in rural areas. Financial Assistance of ₹ 1,20,000 per unit for plain areas; and ₹ 1,30,000 per unit for hilly areas, difficult areas, and IAP districts (Himalayan states, North-Eastern states, and Union Territories of Jammu & Kashmir). A willing beneficiary can avail of institutional finance (loan) of up to ₹ 70,000 at 3% lower interest rate, to build a permanent house. The maximum principal amount for which subsidy can be sought is ₹ 2,00,000. The minimum size of the house shall be is 25 sq m including a dedicated area for hygienic cooking. In convergence with Swachh Bharat Mission-Gramin (SBM-G), the beneficiaries get financial assistance of up to ₹ 12,000 for the construction of toilets. In convergence with MGNREGA, the beneficiary is entitled to employment as unskilled labor (Rural Mason Training) at ₹ 90.95 per day for 95 days. In convergence with Pradhan Mantri Ujjwala Yojana, one LPG connection per house is provided. Convergence with different government programmes for piped drinking water, electricity connection, clean & efficient cooking fuel, treatment of social and liquid waste, etc. Payments are made electronically directly to bank accounts or post office accounts that are linked to Aadhaar. Note: Beneficiaries are identified using the "Housing Deprivation Parameters" from the Socio-Economic and Caste Census (SECC) 2011, further verified by the Gram Sabhas.. The universe of eligible beneficiaries under | H12: 0 | J12: =INT((ROW()-2)/50)+1 -> 1 | K12: =IF(H12="","Pending",IF(OR(H12="0",H12="1",H12="2",H12="U"),"Complete","Invalid")) -> Complete
A13: v2q-024-candidate-10 | B13: v2q-024 | C13: Which national health-assurance programme does NHA implement under the health ministry? | D13: The National Health Authority implements AB-PMJAY under the Ministry of Health and Family Welfare. | E13: pilot-v2-doc-pm-janman-0002-d0844e3327b6 | F13: PM Janjati Adivasi Nyaya Maha Abhiyan (PM JANMAN) | G13: physical survey conducted by state governments using the mobile application on the PM Gati-shakti Portal. Eligibility Specific to Interventions The applicant household seeking a pucca house must currently reside in a kaccha house. The applicant household seeking solar power solutions must be an unelectrified household not covered under the Revamped Distribution Sector Scheme (RDSS). The applicant household seeking an on-grid electricity connection shall be an identified beneficiary household under PM-JANMAN, irrespective of standard eligibility criteria under the Revamped Distribution Sector Scheme (RDSS) for the State and Electricity distribution company (DISCOM).. Step 1: Initiation of Identification and Physical Survey The State Governments initiates a detailed physical survey of each Particularly Vulnerable Tribal Group habitation to ascertain the gaps regarding the 11 critical interventions covered under the mission. The data gathered during this exhaustive survey is simultaneously updated and cross-verified on a mobile application developed on the PM Gati-shakti Portal. Step 2: Facilitation of Application Filing for Eligible Beneficiaries The Block Level Implementation Team, consisting of officers designated by the District Collector, will be responsible for identifying each beneficiary family who has not yet been saturated with entitlements and will facilitate the necessary application filing for the respective schemes. The District Level Committee is also responsible for the registration and filling of applications of eligible beneficiaries for each scheme covered under the mission. Step 3: Verification and Project Approval Following the application filing and preliminary eligibility checks, certain proposals for infrastructure, such as the sanctioning of Multi-Purpose Centers, must be forwarded by the Secretary/Principal Secretary, State Tribal Welfare Department to the Ministry of Tribal Affairs. These proposals are subsequently examined by the relevant division, approved by the Mission Director of PM-JANMAN, and granted financial concurrence by the Internal Finance Division. | H13: 0 | J13: =INT((ROW()-2)/50)+1 -> 1 | K13: =IF(H13="","Pending",IF(OR(H13="0",H13="1",H13="2",H13="U"),"Complete","Invalid")) -> Complete
... A26: v2q-027-candidate-21 | B26: v2q-027 | C26: What livelihood mechanism does PM SVANidhi offer street vendors, and which other programme from its ministry addresses housing shortages for eligible urban households? | D26: PM SVANidhi offers street vendors collateral-free working-capital loans, interest subsidy, and digital-payment incentives. PMAY-U, under the same Ministry of Housing and Urban Affairs, provides housing support for eligible urban households. | E26: pilot-v2-doc-mgnrega-0001-5203a455caa6 | F26: Mahatma Gandhi National Rural Employment Guarantee Act | G26: entitled to a travel and subsistence allowance (10% of the minimum wage). Wages are paid within a week, or fifteen days at most. Men and Women are paid equally. Shade, drinking water, and first-aid are provided at every worksite. Exclusive measures for the promotion of the participation of the disabled persons: Identification of suitable works Mobilization of disabled persons by focussing on awareness and special provisions Specifically identified works for disabled persons in the case of large GPs Preference to appoint as mates and as workers for providing drinking water, to manage crèches, etc., at the worksites Adoption of tools and equipment/facilities at workplaces Treating persons with disabilities with respect Special drive to ensure 100 days of employment to such households Provide a special job card of a distinct color Specific attention and provisions for Senior Citizens: Exclusive senior citizen groups may be formed and special works which require lesser physical effort are identified and allotted to these groups. Specific attention and provisions for Internally Displaced Persons: A special job card to be provided will be valid till these families are displaced and will lose its validity as soon as they return to their original place of residence.. The applicant must be at least 18 years of age. The applicant must be residing in a Rural Area.. NA. Step 1: The application for registration may be given on plain paper to the local Gram Panchayat. An individual may appear personally before the Panchayat Secretary or Gram Rozgar Sahayak and make an oral request for registration, in which case the particulars required will be noted by the Gram Rojgar Sahayak or the Panchayat Secretary. Application for registration should contain names of those adult members of the household who are willing to do unskilled manual work. Particulars such as age, sex, SC/ST | H26: 0 | J26: =INT((ROW()-2)/50)+1 -> 1 | K26: =IF(H26="","Pending",IF(OR(H26="0",H26="1",H26="2",H26="U"),"Complete","Invalid")) -> Complete
A27: v2q-017-candidate-11 | B27: v2q-017 | C27: Which training route serves people no longer in education or work who need an initial occupational skill? | D27: PMKVY 4.0 Short-Term Training provides fresh skilling, reskilling, or upskilling for groups including school or college dropouts and unemployed youth. | E27: pilot-v2-doc-pmkvy-rpl-0001-9ccf0701dcf9 | F27: Pradhan Mantri Kaushal Vikas Yojana 4.0 - Recognition Of Prior Learning | G27: charged to the candidate for pre-screening. Assessment and Certification, with a payout of ₹600 per candidate per assessment provided to the Sector Skill Councils (SSCs) / Awarding Bodies for overseeing and facilitating final assessments. Accidental Insurance with one year of coverage, paid from the scheme (as per prevailing rates, ₹14.16). A T-shirt is provided to the trainee by the RPL-PIA at its own cost. A graded Skill Certificate and Marksheet on passing, with the grade awarded as Grade A (85% and above) or Grade B (70% to less than 85%). Conditions associated with the benefits: The pass percentage for a Qualification Pack (QP) is 70%; a candidate must achieve marks greater than or equal to 70% to be awarded the Skill Certificate. Marks scored in the Core National Occupational Standards (NOS) of a QP are given 70% weightage, and the remaining 30% weightage is from the Non-Core NOS. Certification is at the same NSQF level as determined during pre-screening. AEBAS-based compulsory attendance is applicable, and more than 70% biometric attendance is required to appear for the assessment. Indicative average unit (per-candidate) cost by RPL type RPL with upskilling (30 hours) at an Accredited and Affiliated Training Centre: ₹3,126.18 per candidate. RPL with upskilling (30 hours) at Industry premises: ₹2,826.18 per candidate. RPL with upskilling (60 hours) at an Accredited and Affiliated Training Centre: ₹3,962.88 per candidate. RPL with upskilling (60 hours) at Industry premises: ₹3,662.88 per candidate. (Note on the base cost: a fixed cost of ₹2,000 per candidate applies for RPL at an Accredited and Affiliated Training Centre and ₹1,700 for RPL at Industry premises for 12 hours of training; the reduction of ₹300 at Industry premises is owing to availability of infrastructure and lower mobilisation cost. Additional hours beyond 12 are paid at the discounted Common Norm of | H27: 0 | I27: RPL sub-scheme chunk for STT question — RPL targets experienced workers, not dropouts/unemployed needing initial skills. | J27: =INT((ROW()-2)/50)+1 -> 1 | K27: =IF(H27="","Pending",IF(OR(H27="0",H27="1",H27="2",H27="U"),"Complete","Invalid")) -> Complete
A28: v2q-009-candidate-09 | B28: v2q-009 | C28: What does APY stand for, and what monthly pension range does it guarantee after age 60? | D28: APY stands for Atal Pension Yojana and offers guaranteed monthly pension options from ₹1,000 to ₹5,000 after age 60. | E28: pilot-v2-doc-pm-kisan-guidelines-0001-5ad8f250b7e2 | F28: PM-KISAN Operational Guidelines | G28: i) Former and present holders of constitutional posts ii) Former and present Ministers / State Ministers and former / present Members of Lok Sabha / Rajya Sabha / State Legislative Assemblies / State Legislative Councils, former and present Mayors of Municipal Corporations, former and present Chairpersons of District Panchayats. iii) All serving or retired officers and employees of Central / State Government Ministries / Offices / Departments and their field units, Central or State PSEs and Attached offices / Autonomous Institutions under Government as well as regular 2 employees of the Local Bodies (Excluding Multi Tasking Staff / Class IV / Group D employees) iv) All superannuated / retired pensioners whose monthly pension is Rs.10,000/- or more (Excluding Multi Tasking Staff / Class IV / Group D employees) v) All Persons who paid Income Tax in last assessment year. vi) Professionals like Doctors, Engineers, Lawyers, Chartered Accountants, and Architects registered with Professional bodies and carrying out profession by undertaking practices. (c) In case of new beneficiaries being uploaded on the PM-KISAN Portal, all land holding farmers’ families who are Non-resident Indians (NRIs) in terms of the provisions of the Income Tax Act, 1961 shall be excluded from any benefit under the Scheme. 4.2 For the purpose of exclusion State / UT Governments can certify the eligibility of the beneficiaries based on self declaration by the beneficiaries. In case beneficiary is not available / does not reside in the village, State / UT Governments may consider certification based on the declaration by other adult member of his / her family. In case of incorrect self declaration, beneficiary shall be liable for recovery of transferred financial benefit and other penal actions as per law. 5. Methodology for calculation of benefit 5.1 The benefit shall be paid to only those farmers’ families whose | H28: 0 | J28: =INT((ROW()-2)/50)+1 -> 1 | K28: =IF(H28="","Pending",IF(OR(H28="0",H28="1",H28="2",H28="U"),"Complete","Invalid")) -> Complete
A29: v2q-001-candidate-06 | B29: v2q-001 | C29: What is the minimum house size specified under PMAY-G? | D29: The minimum house size is 25 square metres, including a dedicated hygienic cooking area. | E29: pilot-v2-doc-pmay-u-0000-0b5e95b2690a | F29: Pradhan Mantri Awas Yojana - Urban | G29: Pradhan Mantri Awas Yojana - Urban. Ministry Of Housing & Urban Affairs. The “Pradhan Mantri Awas Yojana – Urban (PMAY-U)” was launched on 25th June 2015 by the Ministry of Housing &amp; Urban Affairs, Government of India with the vision of “Housing for All” to provide pucca houses to eligible urban households. Implemented by the Ministry of Housing and Urban Affairs, the scheme addresses urban housing shortages, especially for EWS, LIG, and MIG categories, including slum dwellers. It promotes affordable and sustainable housing through components like the Credit Linked Subsidy Scheme (CLSS), offering interest subsidies on housing loans. The mission covers all statutory towns and notified urban areas as per Census 2011. Aadhaar is mandatory for all eligible beneficiaries under the scheme.. Pradhan Mantri Awas Yojana - Urban (PMAY-U) Scheme was launched on 25th June 2015 by the Hon’ble Prime Minister to provide all-weather pucca houses to all eligible urban households across the nation with the vision of ‘Housing for All’.. States/UTsBLC &amp;amp;amp; AHPARHISSAssam, Arunachal Pradesh, Meghalaya, Manipur, Mizoram, Nagaland, Tripura, Sikkim, Himachal Pradesh, Uttarakhand, UTs of Jammu and Kashmir, Puducherry, and DelhiCentral Govt. - ₹2.25 lakh/Unit; State Govt. - Min. ₹0.25 lakh/UnitTechnology Innovation Grant Central Govt. - ₹3,000/sqm per unit State Govt.- ₹2,000/sqm per unit Home Loan Subsidy – up to ₹1.80 lakh (Actual Release) per unit by the Government of India as a Central Sector SchemeAll other UTsCentral Govt. - ₹2.50 lakh/UnitDoDoAll other StatesCentral Govt. - ₹1.5 lakh/Unit; State Govt. - Min. ₹1.00 lakh/UnitDoDo. The family identifies as one of the following - a) Economically Weaker Section (EWS): households with annual income up to ₹3,00,000. b) Low Income Group (LIG): households with annual income between ₹3,00,001 and ₹6,00,000. c) Middle Income Group-1 (MIG-1): households with annual income between ₹6,00,001 and ₹12,00,000. d) Middle Income Group-2 (MIG-2): households with | H29: 0 | J29: =INT((ROW()-2)/50)+1 -> 1 | K29: =IF(H29="","Pending",IF(OR(H29="0",H29="1",H29="2",H29="U"),"Complete","Invalid")) -> Complete
A30: v2q-003-candidate-20 | B30: v2q-003 | C30: What revised overdraft limit and RuPay accidental-insurance cover are stated for PMJDY? | D30: PMJDY states a revised overdraft limit of ₹10,000 and accidental-insurance cover of ₹2 lakh for RuPay cardholders. | E30: pilot-v2-doc-ab-pmjay-0002-58c80bb24a6c | F30: Ayushman Bharat - Pradhan Mantri Jan Arogya Yojana | G30: deriving a major part of their income from manual casual labour Automatically includedHouseholds without shelter Destitute/ living on alms, Manual scavenger families, Primitive tribal groups, Legally released bonded labour. Urban Beneficiaries For urban areas, the following 11 occupational categories of workers are eligible for the scheme: Ragpicker Beggar Domestic worker Street vendor/ Cobbler/hawker / other service provider working on streets Construction worker/ Plumber/ Mason/ Labour/ Painter/ Welder/ Security guard/ Coolie and other head-load worker Sweeper/ Sanitation worker/ Mali Home-based worker/ Artisan/ Handicrafts worker/ Tailor Transport worker/ Driver/ Conductor/ Helper to drivers and conductors/ Cart puller/ Rickshaw puller Shop worker/ Assistant/ Peon in small establishment/ Helper/Delivery assistant / Attendant/ Waiter Electrician/ Mechanic/ Assembler/ Repair worker Washer-man/ Chowkidar. Those who own a two, three, or four-wheeler or a motorized fishing boat. Those who own mechanized farming equipment. Those who have Kisan cards with a credit limit of ₹50,000/-. Those employed by the government. Those who work in government-managed non-agricultural enterprises. Those earning a monthly income above ₹10,000/-. Those owning refrigerators and landlines. Those with decent, solidly built houses. Those owning 5 acres or more of agricultural land.. The Arogya Mitra searches the available list of beneficiaries using details such as name, location, ration card number, mobile number, or the RSBY URN of the beneficiary. After this, the beneficiary is searched for in the BIS. The individual is identified and the scanned valid ID documents are then uploaded. To get a PMJAY e-card for themselves and their family, a potential beneficiary needs to visit either a hospital or a Community Service Centre (CSC) for identification and follow the steps mentioned below: Step 1: Potential AB-PMJAY beneficiaries are to submit the PM letter/ RSBY URN/ RC Number/ Mobile Number - The operator (commonly known as the Arogya Mitra) searches the available list of beneficiaries. | H30: 0 | J30: =INT((ROW()-2)/50)+1 -> 1 | K30: =IF(H30="","Pending",IF(OR(H30="0",H30="1",H30="2",H30="U"),"Complete","Invalid")) -> Complete
A31: v2q-028-candidate-01 | B31: v2q-028 | C31: What does PMKVY Recognition of Prior Learning certify, and which other pathway from its ministry serves candidates seeking fresh short-term skills training? | D31: PMKVY Recognition of Prior Learning certifies candidates’ existing skills. PMKVY Short-Term Training, under the same Ministry of Skill Development and Entrepreneurship, provides fresh skilling, reskilling, or upskilling. | E31: pilot-v2-doc-pmkvy-sp-0002-dc58b95bab9b | F31: Pradhan Mantri Kaushal Vikas Yojana 4.0- Special Projects | G31: Special Areas, and may also be extended for training in Aspirational, Border, Tribal-dominated, and LWE-affected districts. Special Projects may also be taken up with fully residential training.1. Conveyance / Transportation Cost: Permissible for Women and Persons with Disability (PwD) in case of non-residential training, as per Common Norms.1. Additional Support to Persons with Disability (PwD) Candidates: ₹5,000 towards assistive devices, aids, and appliances.1. Accidental Insurance: Every certified candidate is provided with 1-year accidental insurance, as per prevailing rates (₹14.16).1. Aadhaar Enabled Biometric Attendance System (AEBAS) Transaction Fees: Up to ₹10 per user, borne under the scheme.1. Post-Certification Tracking Support: Information Technology (IT)-based tracking for up to 1 year from the date of certification, with an allowance of up to ₹50 per certified candidate.1. Certification: A Quick Response (QR) code-based digital certificate is issued (on DigiLocker, on email/phone number, and on the Skill India Digital profile), and one printed certificate is provided free of cost by the Training Provider.1. Post-Certification Linkages: Certified candidates are linked with Rojgar Melas (including virtual) and Apprenticeship Melas and gain access to jobs, apprenticeship opportunities, and loans for entrepreneurship through Skill India Digital.. The applicant should be of Indian nationality. The applicant should possess a valid Aadhaar. The applicant should fulfil the eligibility criteria of the respective job role. The applicant should be in the age group of 15 to 45 years. The applicant should belong to a marginalised or vulnerable group, or another group requiring special attention, or should be undertaking job roles with a focus on future skills.. The applicant should not be enrolled again in the same job role in which he/she was trained earlier. The applicant, if already certified once under PMKVY, will be discouraged from opting for a lower National Skills Qualification Framework (NSQF) level course in the same sector; however, | H31: 1 | J31: =INT((ROW()-2)/50)+1 -> 1 | K31: =IF(H31="","Pending",IF(OR(H31="0",H31="1",H31="2",H31="U"),"Complete","Invalid")) -> Complete
A32: v2q-023-candidate-24 | B32: v2q-023 | C32: What role does a Gram Panchayat play when a household registers for MGNREGA? | D32: A household may apply through its local Gram Panchayat, which verifies residence, household identity, and adult membership details. | E32: pilot-v2-doc-pm-gkay-0001-ccd31e120258 | F32: Pradhan Mantri Garib Kalyan Anna Yojana | G32: scheme aims to ensure food security for the poor. Through this scheme, free foodgrains are provided to eligible ration card holders under the National Food Security Act, 2013.. Antyodaya Anna Yojana (AAY) families receive 35 kilograms of foodgrains per family per month. Priority Household (PHH) beneficiaries receive 5 kilograms of foodgrains per person per month. The foodgrains are provided as rice or wheat, depending on the state, with fortified rice distributed nationwide. Since January 2023, the foodgrains have been provided completely free of cost (at zero cost) to the beneficiaries. Through One Nation One Ration Card, beneficiaries can collect their ration from any fair price shop anywhere in India.. The applicant should be a household belonging to the Antyodaya Anna Yojana (AAY) category or the Priority Households (PHH) category. Priority Households (PHH) are to be identified by the state governments/union territory administrations as per the criteria evolved by them. Antyodaya Anna Yojana (AAY) families are to be identified by the States / Union Territories as per the criteria prescribed by the Central Government, as listed below. Criteria for Antyodaya Anna Yojana (AAY) Families: The applicant should be a household headed by a widow, a terminally ill person, a disabled person, or a person aged 60 years or more, with no assured means of subsistence or societal support. The applicant should be a widow, a terminally ill person, a disabled person, a person aged 60 years or more, a single woman, or a single man, with no family or societal support, and with no assured means of subsistence. The applicant should belong to a primitive tribal household. The applicant should be a landless agricultural laborer, a marginal farmer, or a rural artisan or craftsman (such as a potter, tanner, weaver, blacksmith, or carpenter); a slum dweller; or a person earning a | H32: 0 | J32: =INT((ROW()-2)/50)+1 -> 1 | K32: =IF(H32="","Pending",IF(OR(H32="0",H32="1",H32="2",H32="U"),"Complete","Invalid")) -> Complete
A33: v2q-004-candidate-01 | B33: v2q-004 | C33: What is the maximum micro-loan amount stated for PMMY? | D33: PMMY facilitates micro-credit loans up to ₹20 lakh for eligible income-generating micro-enterprises. | E33: pilot-v2-doc-pmay-g-0001-db2db8af1543 | F33: Pradhan Mantri Awaas Yojana - Gramin | G33: years from 2016-17 to 2018-19 and enable construction of quality houses by the beneficiaries using local materials, designs and trained masons. For houses to become homes, adoption of a habitat approach through convergence is proposed.. Launch on 1st April 2016, Pradhan Mantri Awaas Yojana Gramin (PMAY-G) is centre's flagship mission by the Ministry of Rural Development (MoRD), implemented by the Ministry of Housing and Urban Affairs (MoHUA). PMAY-G addresses the rural housing shortage and bridges the housing deficit in rural areas. Financial Assistance of ₹ 1,20,000 per unit for plain areas; and ₹ 1,30,000 per unit for hilly areas, difficult areas, and IAP districts (Himalayan states, North-Eastern states, and Union Territories of Jammu & Kashmir). A willing beneficiary can avail of institutional finance (loan) of up to ₹ 70,000 at 3% lower interest rate, to build a permanent house. The maximum principal amount for which subsidy can be sought is ₹ 2,00,000. The minimum size of the house shall be is 25 sq m including a dedicated area for hygienic cooking. In convergence with Swachh Bharat Mission-Gramin (SBM-G), the beneficiaries get financial assistance of up to ₹ 12,000 for the construction of toilets. In convergence with MGNREGA, the beneficiary is entitled to employment as unskilled labor (Rural Mason Training) at ₹ 90.95 per day for 95 days. In convergence with Pradhan Mantri Ujjwala Yojana, one LPG connection per house is provided. Convergence with different government programmes for piped drinking water, electricity connection, clean & efficient cooking fuel, treatment of social and liquid waste, etc. Payments are made electronically directly to bank accounts or post office accounts that are linked to Aadhaar. Note: Beneficiaries are identified using the "Housing Deprivation Parameters" from the Socio-Economic and Caste Census (SECC) 2011, further verified by the Gram Sabhas.. The universe of eligible beneficiaries under | H33: 0 | J33: =INT((ROW()-2)/50)+1 -> 1 | K33: =IF(H33="","Pending",IF(OR(H33="0",H33="1",H33="2",H33="U"),"Complete","Invalid")) -> Complete
A34: v2q-019-candidate-11 | B34: v2q-019 | C34: What role does the Ministry of Petroleum and Natural Gas have in Ujjwala 2.0? | D34: The ministry introduced Ujjwala 2.0 to provide LPG connections and promote clean cooking fuel among poor, rural, and deprived households. | E34: pilot-v2-doc-pmay-g-0001-db2db8af1543 | F34: Pradhan Mantri Awaas Yojana - Gramin | G34: years from 2016-17 to 2018-19 and enable construction of quality houses by the beneficiaries using local materials, designs and trained masons. For houses to become homes, adoption of a habitat approach through convergence is proposed.. Launch on 1st April 2016, Pradhan Mantri Awaas Yojana Gramin (PMAY-G) is centre's flagship mission by the Ministry of Rural Development (MoRD), implemented by the Ministry of Housing and Urban Affairs (MoHUA). PMAY-G addresses the rural housing shortage and bridges the housing deficit in rural areas. Financial Assistance of ₹ 1,20,000 per unit for plain areas; and ₹ 1,30,000 per unit for hilly areas, difficult areas, and IAP districts (Himalayan states, North-Eastern states, and Union Territories of Jammu & Kashmir). A willing beneficiary can avail of institutional finance (loan) of up to ₹ 70,000 at 3% lower interest rate, to build a permanent house. The maximum principal amount for which subsidy can be sought is ₹ 2,00,000. The minimum size of the house shall be is 25 sq m including a dedicated area for hygienic cooking. In convergence with Swachh Bharat Mission-Gramin (SBM-G), the beneficiaries get financial assistance of up to ₹ 12,000 for the construction of toilets. In convergence with MGNREGA, the beneficiary is entitled to employment as unskilled labor (Rural Mason Training) at ₹ 90.95 per day for 95 days. In convergence with Pradhan Mantri Ujjwala Yojana, one LPG connection per house is provided. Convergence with different government programmes for piped drinking water, electricity connection, clean & efficient cooking fuel, treatment of social and liquid waste, etc. Payments are made electronically directly to bank accounts or post office accounts that are linked to Aadhaar. Note: Beneficiaries are identified using the "Housing Deprivation Parameters" from the Socio-Economic and Caste Census (SECC) 2011, further verified by the Gram Sabhas.. The universe of eligible beneficiaries under | H34: 0 | J34: =INT((ROW()-2)/50)+1 -> 1 | K34: =IF(H34="","Pending",IF(OR(H34="0",H34="1",H34="2",H34="U"),"Complete","Invalid")) -> Complete
A35: v2q-029-candidate-04 | B35: v2q-029 | C35: What migrant-focused facility distinguishes Ujjwala 2.0, and what clean-cooking transition was established by its predecessor programme? | D35: Ujjwala 2.0 added 1.6 crore LPG connections with a special facility for migrant households. Its predecessor, Pradhan Mantri Ujjwala Yojana, sought to replace traditional cooking fuels with LPG access for rural and deprived households. | E35: pilot-v2-doc-pmay-g-0002-e08c1e347071 | F35: Pradhan Mantri Awaas Yojana - Gramin | G35: electricity connection, clean & efficient cooking fuel, treatment of social and liquid waste, etc. Payments are made electronically directly to bank accounts or post office accounts that are linked to Aadhaar. Note: Beneficiaries are identified using the "Housing Deprivation Parameters" from the Socio-Economic and Caste Census (SECC) 2011, further verified by the Gram Sabhas.. The universe of eligible beneficiaries under PMAY-G will include all the houseless households living in zero, one, or two-room houses with kutcha walls and kutcha roofs (as per SECC data, and subject to the exclusion process). Criteria for Automatic/Compulsory Inclusion - 1. Households without shelter 2. Destitute/ living on alms 3. Manual scavengers 4. Primitive Tribal Groups 5. Legally released bonded laborer Prioritisation within the Universe i. There will be multilayered prioritization within the universe of eligible PMAY-G beneficiaries. Priority will first be assigned on the basis of parameters reflecting housing deprivation in each category viz., SC/ST, Minorities, and Others. ii. To begin with, households will be prioritized based on houselessness followed by the number of rooms; zero, one, and two rooms, in that order. iii. In a particular social category viz., SC/ST, Minorities, and Others, households that are houseless or living in houses with a lower number of rooms shall not be ranked below households living in houses with a higher number of rooms. Within the above priority groups, households that fulfill the criteria of "compulsory inclusion", will be further elevated. Automatically included households shall not rank lower than other households within a priority group. Inter-se priority within the two subgroups viz. households which are automatically included and otherwise will be determined based on their cumulative deprivation scores. The scores will be calculated from the socio-economic parameters given below with each having equal weight: i. Households with no adult member between ages 16 to 59 | H35: 0 | J35: =INT((ROW()-2)/50)+1 -> 1 | K35: =IF(H35="","Pending",IF(OR(H35="0",H35="1",H35="2",H35="U"),"Complete","Invalid")) -> Complete
A36: v2q-026-candidate-21 | B36: v2q-026 | C36: What employment guarantee does MGNREGA provide, and which other programme from its ministry supplies pucca houses to rural households? | D36: MGNREGA guarantees at least 100 days of wage employment to qualifying rural households. PMAY-G, under the same Ministry of Rural Development, supports pucca houses with basic amenities for eligible rural households. | E36: pilot-v2-doc-pmay-g-0004-f8ee90715c3f | F36: Pradhan Mantri Awaas Yojana - Gramin | G36: such. In case all eligible SC and ST households are covered, the State/ UT targets would be allocated to beneficiaries from the 'Other' categories included in the Permanent Wait List drawn from SECC 2011. For Minorities: Further, as far as possible, 15% of the total fund would be earmarked for Minorities at the National Level for households. The allocation of targets for Minorities among the States/UTs will be on the basis of the proportionate rural population of Minorities in the respective State/UT as per Census 2011 data. Minorities notified under Section 2(c) of the National Commission for Minorities Act, 1992 are to be considered eligible for receiving benefits against Minority earmarks. For PwDs: Accordingly, in the scheme of PMAY-G, while deciding the inter-se priority among the beneficiaries who are to be provided assistance, households with any disabled member and no able-bodied adult member have been accorded additional deprivation score so that such households are given priority while allotting the houses. Keeping in view the provisions of the Persons with Disabilities Act, of 1995, the States to the extent possible, may ensure that 3% of beneficiaries at the State Level are from among persons with disabilities. Tie Breaker In case there is a tie with more than one household within a subgroup having the same deprivation score, the households will be ranked according to priority on the basis of the following parameters: i. Households with widows and next-of-kin of members of defence/paramilitary/police forces killed in action. ii. Households where a member is suffering from leprosy or cancer and People living with HIV (PLHIV). iii. Households with a single girl child. iv. Beneficiary families of the Scheduled Tribes and Other Traditional Forest Dwellers (Recognition of Forest Rights) Act, 2006, commonly known as the Forest Rights Act. v. Transgender persons.. Step 1: Exclusion | H36: 1 | J36: =INT((ROW()-2)/50)+1 -> 1 | K36: =IF(H36="","Pending",IF(OR(H36="0",H36="1",H36="2",H36="U"),"Complete","Invalid")) -> Complete
